<?xml version="1.0" ?>
<robot name="arm_lwa4d">
  <material name="Neobotix/Black">
        <color rgba="0.0 0.0 0.0 1.0"/>
    </material>

    <material name="Neobotix/Blue">
        <color rgba="0.0 0.0 0.8 1.0"/>
    </material>

    <material name="Neobotix/Green">
        <color rgba="0.0 0.8 0.0 1.0"/>
    </material>

    <material name="Neobotix/Grey">
        <color rgba="0.7 0.7 0.7 1.0"/>
    </material>

    <material name="Neobotix/Grey2">
        <color rgba="0.9 0.9 0.9 1.0"/>
    </material>

    <material name="Neobotix/Red">
        <color rgba="0.8 0.0 0.0 1.0"/>
    </material>

    <material name="Neobotix/White">
        <color rgba="1.0 1.0 1.0 1.0"/>
    </material>

    <material name="Neobotix/Yellow">
        <color rgba="1.0 1.0 0 10" />
    </material>

    <material name="Schunk/LightGrey">
        <color rgba="0.7 0.7 0.7 1.0"/>
    </material>

    <material name="Schunk/DarkGrey">
        <color rgba="0.4 0.4 0.4 1.0"/>
    </material>

    <material name="Schunk/Black">
        <color rgba="0.0 0.0 0.0 1.0"/>
    </material>

    <material name="Schunk/DarkGolden">
        <color rgba="0.4 0.4 0.3 1.0"/>
    </material>

    <material name="Schunk/Blue">
        <color rgba="0.0 0.0 0.8 1.0"/>
    </material>

  <!--+++++++++++++++ arm_podest_joint +++++++++++++++++++++++++++-->
   <!--<joint name="arm_podest_joint" type="fixed">-->
      <!--<origin xyz="0.19 0 0.36" rpy="0 0 0" />-->
      <!--<parent link="base_link"/>-->
      <!--<child link="arm_podest_link"/>-->
   <!--</joint>-->

<!--+++++++++++++++ arm_podest_link +++++++++++++++++++++++++++-->
  <link name="arm_podest_link">
      <inertial>
          <mass value="0.01" />
          <origin xyz="0 0 0" />
          <inertia ixx="0.001" ixy="0.0" ixz="0.0" iyy="0.001" iyz="0.0" izz="0.001" />
      </inertial>
      <visual>
          <geometry>
              <mesh filename="/home/lei/Documents/Projektpraktikum/Pybullet/bullet3/examples/pybullet/gym/pybullet_data/neobotixschunk/meshes/arm_podest_link.stl"/>
          </geometry>
          <material name="Schunk/LightGrey"/>
      </visual>
      <collision>
          <geometry>
              <mesh filename="/home/lei/Documents/Projektpraktikum/Pybullet/bullet3/examples/pybullet/gym/pybullet_data/neobotixschunk/meshes/arm_podest_link.stl"/>
          </geometry>
      </collision>
  </link>

<!--+++++++++++++++ arm_base_joint +++++++++++++++++++++++++++-->
   <joint name="arm_base_joint" type="fixed">
        <origin xyz="0 0 0.140" rpy="0 0 0" />
        <axis xyz="0 0 1"/>
        <parent link="arm_podest_link"/>
        <child link="arm_base_link"/>
   </joint>

<!--+++++++++++++++ arm_base_link +++++++++++++++++++++++++++-->
   <link name="arm_base_link">
      <inertial>
          <mass value="0.01" />
          <origin xyz="0 0 0" />
          <inertia ixx="0.001" ixy="0.0" ixz="0.0" iyy="0.001" iyz="0.0" izz="0.001" />
      </inertial>
   </link>

<!--+++++++++++++++joint between arm_base_link and arm_1_link +++++++++++++++-->
    <joint name="arm_1_joint" type="revolute">
        <origin xyz="0 0 0" rpy="0 0 0" />
        <axis xyz="0 0 1"/>
        <parent link="arm_base_link"/>
        <child link="arm_1_link"/>
        <limit effort="216" velocity="0.43633" lower="-3.1215926" upper="3.1215926"/>
    </joint>


<!--+++++++++++++++ arm_1_link+++++++++++++++-->
   <link name="arm_1_link">
       <inertial>
           <mass value="0.01" />
           <origin xyz="0 0 0" />
           <inertia ixx="0.001" ixy="0.0" ixz="0.0" iyy="0.001" iyz="0.0" izz="0.001" />
       </inertial>
       <visual>
           <geometry>
               <mesh filename="/home/lei/Documents/Projektpraktikum/Pybullet/bullet3/examples/pybullet/gym/pybullet_data/neobotixschunk/meshes/arm_1_link.stl"/>
           </geometry>
           <material name="Schunk/LightGrey"/>
       </visual>
       <collision>
           <geometry>
               <mesh filename="/home/lei/Documents/Projektpraktikum/Pybullet/bullet3/examples/pybullet/gym/pybullet_data/neobotixschunk/meshes/arm_1_link.stl"/>
           </geometry>
       </collision>
   </link>

<!-- +++++++++++++++joint between arm_1_link and arm_2_link +++++++++++++++-->
    <joint name="arm_2_joint" type="revolute">
      <origin xyz="0 0 0.24" rpy="-1.5707963 -1.5707963 0"/>
      <axis xyz="0 0 1"/>
      <parent link="arm_1_link"/>
      <child link="arm_2_link"/>
      <limit effort="216" velocity="0.43633" lower="-2.12" upper="2.12"/>
    </joint>


<!--+++++++++++++++ arm_2_link +++++++++++++++-->
    <link name="arm_2_link">
        <inertial>
            <mass value="0.01" />
            <origin xyz="0 0 0" />
            <inertia ixx="0.001" ixy="0.0" ixz="0.0" iyy="0.001" iyz="0.0" izz="0.001" />
        </inertial>
        <visual>
            <geometry>
                <mesh filename="/home/lei/Documents/Projektpraktikum/Pybullet/bullet3/examples/pybullet/gym/pybullet_data/neobotixschunk/meshes/arm_2_link.stl"/>
            </geometry>
            <material name="Schunk/Black"/>
        </visual>
        <collision>
            <geometry>
                <mesh filename="/home/lei/Documents/Projektpraktikum/Pybullet/bullet3/examples/pybullet/gym/pybullet_data/neobotixschunk/meshes/arm_2_link_collision.stl"/>
            </geometry>
        </collision>
    </link>

<!--+++++++++++++++ joint between arm_2_link and arm_3_link +++++++++++++++-->
    <joint name="arm_3_joint" type="revolute">
      <origin xyz="0 0 0" rpy="1.5707963 0 1.5707963"/>
      <axis xyz="0 0 1"/>
      <parent link="arm_2_link"/>
      <child link="arm_3_link"/>
      <limit effort="81.5" velocity="0.4189" lower="-3.1215926" upper="3.1215926"/>
    </joint>


<!--+++++++++++++++ arm_3_link +++++++++++++++-->
   <link name="arm_3_link">
       <inertial>
           <mass value="0.01" />
           <origin xyz="0 0 0" />
           <inertia ixx="0.001" ixy="0.0" ixz="0.0" iyy="0.001" iyz="0.0" izz="0.001" />
       </inertial>
       <visual>
           <geometry>
               <mesh filename="/home/lei/Documents/Projektpraktikum/Pybullet/bullet3/examples/pybullet/gym/pybullet_data/neobotixschunk/meshes/arm_3_link.stl"/>
           </geometry>
           <material name="Schunk/LightGrey"/>
       </visual>
       <collision>
           <geometry>
               <mesh filename="/home/lei/Documents/Projektpraktikum/Pybullet/bullet3/examples/pybullet/gym/pybullet_data/neobotixschunk/meshes/arm_3_link_collision.stl"/>
           </geometry>
       </collision>
   </link>

<!--+++++++++++++++ joint between arm_3_link and arm_4_link +++++++++++++++-->
    <joint name="arm_4_joint" type="revolute">
      <origin xyz="0 0 0.328" rpy="-1.5707963 -1.5707963 0"/>
      <axis xyz="0 0 1"/>
      <parent link="arm_3_link"/>
      <child link="arm_4_link"/>
      <limit effort="81.5" velocity="0.4189" lower="-2.16" upper="2.16"/>
    </joint>


<!--+++++++++++++++arm_4_link +++++++++++++++-->
    <link name="arm_4_link">
        <inertial>
            <mass value="0.01" />
            <origin xyz="0 0 0" />
            <inertia ixx="0.001" ixy="0.0" ixz="0.0" iyy="0.001" iyz="0.0" izz="0.001" />
        </inertial>
        <visual>
            <geometry>
                <mesh filename="/home/lei/Documents/Projektpraktikum/Pybullet/bullet3/examples/pybullet/gym/pybullet_data/neobotixschunk/meshes/arm_4_link.stl"/>
            </geometry>
            <material name="Schunk/Black"/>
        </visual>
        <collision>
            <geometry>
                <mesh filename="/home/lei/Documents/Projektpraktikum/Pybullet/bullet3/examples/pybullet/gym/pybullet_data/neobotixschunk/meshes/arm_4_link_collision.stl"/>
            </geometry>
        </collision>
    </link>

<!--+++++++++++++++ joint between arm_4_link and arm_5_link+++++++++++++++ -->
    <joint name="arm_5_joint" type="revolute">
      <origin xyz="0 0 0" rpy="1.5707963 0 1.5707963"/>
      <axis xyz="0 0 1"/>
      <parent link="arm_4_link"/>
      <child link="arm_5_link"/>
      <limit effort="20.7" velocity="0.43633" lower="-3.1215926" upper="3.1215926"/>
    </joint>


<!-- +++++++++++++++arm_5_link +++++++++++++++-->
    <link name="arm_5_link">
        <inertial>
            <mass value="0.01" />
            <origin xyz="0 0 0" />
            <inertia ixx="0.001" ixy="0.0" ixz="0.0" iyy="0.001" iyz="0.0" izz="0.001" />
        </inertial>
        <visual>
            <geometry>
                <mesh filename="/home/lei/Documents/Projektpraktikum/Pybullet/bullet3/examples/pybullet/gym/pybullet_data/neobotixschunk/meshes/arm_5_link.stl"/>
            </geometry>
            <material name="Schunk/LightGrey"/>
        </visual>
        <collision>
            <geometry>
                <mesh filename="/home/lei/Documents/Projektpraktikum/Pybullet/bullet3/examples/pybullet/gym/pybullet_data/neobotixschunk/meshes/arm_5_link_collision.stl"/>
            </geometry>
        </collision>
    </link>

<!--+++++++++++++++ joint between arm_5_link and arm_6_link +++++++++++++++-->
    <joint name="arm_6_joint" type="revolute">
      <origin xyz="0 0 0.323" rpy="-1.5707963 -1.5707963 0"/>
      <axis xyz="0 0 1"/>
      <parent link="arm_5_link"/>
      <child link="arm_6_link"/>
      <limit effort="15" velocity="1.2566" lower="-2.07" upper="2.07"/>
    </joint>


<!--+++++++++++++++ arm_6_link +++++++++++++++-->
    <link name="arm_6_link">
        <inertial>
            <mass value="0.01" />
            <origin xyz="0 0 0" />
            <inertia ixx="0.001" ixy="0.0" ixz="0.0" iyy="0.001" iyz="0.0" izz="0.001" />
        </inertial>
        <visual>
            <geometry>
                <mesh filename="/home/lei/Documents/Projektpraktikum/Pybullet/bullet3/examples/pybullet/gym/pybullet_data/neobotixschunk/meshes/arm_6_link.stl"/>
            </geometry>
            <material name="Schunk/Black"/>
        </visual>
        <collision>
            <geometry>
                <mesh filename="/home/lei/Documents/Projektpraktikum/Pybullet/bullet3/examples/pybullet/gym/pybullet_data/neobotixschunk/meshes/arm_6_link_collision.stl"/>
            </geometry>
        </collision>
     </link>

<!--+++++++++++++++ joint between arm_6_link and arm_7_link+++++++++++++++ -->
    <joint name="arm_7_joint" type="revolute">
      <origin xyz="0 0 0" rpy="1.5707963 0 1.5707963"/>
      <axis xyz="0 0 1"/>
      <parent link="arm_6_link"/>
      <child link="arm_7_link"/>
      <limit effort="15" velocity="1.2566" lower="-2.94" upper="2.94"/>
    </joint>


<!--+++++++++++++++arm_7_link +++++++++++++++-->
    <link name="arm_7_link">
        <inertial>
            <mass value="0.01" />
            <origin xyz="0 0 0" />
            <inertia ixx="0.001" ixy="0.0" ixz="0.0" iyy="0.001" iyz="0.0" izz="0.001" />
        </inertial>
        <visual>
            <geometry>
                <mesh filename="/home/lei/Documents/Projektpraktikum/Pybullet/bullet3/examples/pybullet/gym/pybullet_data/neobotixschunk/meshes/arm_7_link.stl"/>
            </geometry>
            <material name="Schunk/LightGrey"/>
        </visual>
        <collision>
            <geometry>
                <mesh filename="/home/lei/Documents/Projektpraktikum/Pybullet/bullet3/examples/pybullet/gym/pybullet_data/neobotixschunk/meshes/arm_7_link.stl"/>
            </geometry>
        </collision>
    </link>
<!--+++++++++++++++ arm_ee_joint +++++++++++++++++++++++++++-->
    <joint name="arm_ee_joint" type="fixed">
      <origin xyz="0 0 0.0824" rpy="0 0 0"/>
      <axis xyz="0 0 1"/>
      <parent link="arm_7_link"/>
      <child link="arm_ee_link"/>
    </joint>

<!--+++++++++++++++ arm_ee_link +++++++++++++++++++++++++++-->
    <link name="arm_ee_link">
        <inertial>
            <mass value="0.01" />
            <origin xyz="0 0 0" />
            <inertia ixx="0.001" ixy="0.0" ixz="0.0" iyy="0.001" iyz="0.0" izz="0.001" />
        </inertial>
    </link>

</robot>
